Workbook

Sheet Summary
A1: Sparsh Magic HRMS - Phase 1 FRD v1.1: Build Status
A2: Source: 'Sparsh_Magic_HRMS_Phase1_FRD_v1_1_Configurable_Fields_Rules_Policies.pdf'. Status = HRMS code at commit 5cffdc2 plus the work of 24 Oct 2026 (marked NEW / DONE, not yet committed).
A3: Legend: Built = in place and tested; Partially Built = exists with a stated gap; Missing = not built; Pending Client Decision = FRD leaves the value open.
A5: FRD Section | B5: Built | C5: Partially Built | D5: Missing | E5: Pending Client Decision | F5: Total | G5: % Built
A6: 3. Employee Information | B6: =COUNTIFS('FRD Field Status'!$B$5:$B$401,$A6,'FRD Field Status'!$E$5:$E$401,"Built") | C6: =COUNTIFS('FRD Field Status'!$B$5:$B$401,$A6,'FRD Field Status'!$E$5:$E$401,"Partially Built") | D6: =COUNTIFS('FRD Field Status'!$B$5:$B$401,$A6,'FRD Field Status'!$E$5:$E$401,"Missing") | E6: =COUNTIFS('FRD Field Status'!$B$5:$B$401,$A6,'FRD Field Status'!$E$5:$E$401,"Pending Client Decision") | F6: =SUM(B6:E6) | G6: =IF(F6=0,0,B6/F6)
A7: 4. Employee Creation / Change Process | B7: =COUNTIFS('FRD Field Status'!$B$5:$B$401,$A7,'FRD Field Status'!$E$5:$E$401,"Built") | C7: =COUNTIFS('FRD Field Status'!$B$5:$B$401,$A7,'FRD Field Status'!$E$5:$E$401,"Partially Built") | D7: =COUNTIFS('FRD Field Status'!$B$5:$B$401,$A7,'FRD Field Status'!$E$5:$E$401,"Missing") | E7: =COUNTIFS('FRD Field Status'!$B$5:$B$401,$A7,'FRD Field Status'!$E$5:$E$401,"Pending Client Decision") | F7: =SUM(B7:E7) | G7: =IF(F7=0,0,B7/F7)
A8: 5. Attendance Configuration | B8: =COUNTIFS('FRD Field Status'!$B$5:$B$401,$A8,'FRD Field Status'!$E$5:$E$401,"Built") | C8: =COUNTIFS('FRD Field Status'!$B$5:$B$401,$A8,'FRD Field Status'!$E$5:$E$401,"Partially Built") | D8: =COUNTIFS('FRD Field Status'!$B$5:$B$401,$A8,'FRD Field Status'!$E$5:$E$401,"Missing") | E8: =COUNTIFS('FRD Field Status'!$B$5:$B$401,$A8,'FRD Field Status'!$E$5:$E$401,"Pending Client Decision") | F8: =SUM(B8:E8) | G8: =IF(F8=0,0,B8/F8)
A9: 6. Daily Attendance Fields | B9: =COUNTIFS('FRD Field Status'!$B$5:$B$401,$A9,'FRD Field Status'!$E$5:$E$401,"Built") | C9: =COUNTIFS('FRD Field Status'!$B$5:$B$401,$A9,'FRD Field Status'!$E$5:$E$401,"Partially Built") | D9: =COUNTIFS('FRD Field Status'!$B$5:$B$401,$A9,'FRD Field Status'!$E$5:$E$401,"Missing") | E9: =COUNTIFS('FRD Field Status'!$B$5:$B$401,$A9,'FRD Field Status'!$E$5:$E$401,"Pending Client Decision") | F9: =SUM(B9:E9) | G9: =IF(F9=0,0,B9/F9)
A10: 8. Attendance Processing & Monthly Closure | B10: =COUNTIFS('FRD Field Status'!$B$5:$B$401,$A10,'FRD Field Status'!$E$5:$E$401,"Built") | C10: =COUNTIFS('FRD Field Status'!$B$5:$B$401,$A10,'FRD Field Status'!$E$5:$E$401,"Partially Built") | D10: =COUNTIFS('FRD Field Status'!$B$5:$B$401,$A10,'FRD Field Status'!$E$5:$E$401,"Missing") | E10: =COUNTIFS('FRD Field Status'!$B$5:$B$401,$A10,'FRD Field Status'!$E$5:$E$401,"Pending Client Decision") | F10: =SUM(B10:E10) | G10: =IF(F10=0,0,B10/F10)
A11: 9. Salary Structure Fields | B11: =COUNTIFS('FRD Field Status'!$B$5:$B$401,$A11,'FRD Field Status'!$E$5:$E$401,"Built") | C11: =COUNTIFS('FRD Field Status'!$B$5:$B$401,$A11,'FRD Field Status'!$E$5:$E$401,"Partially Built") | D11: =COUNTIFS('FRD Field Status'!$B$5:$B$401,$A11,'FRD Field Status'!$E$5:$E$401,"Missing") | E11: =COUNTIFS('FRD Field Status'!$B$5:$B$401,$A11,'FRD Field Status'!$E$5:$E$401,"Pending Client Decision") | F11: =SUM(B11:E11) | G11: =IF(F11=0,0,B11/F11)
A12: 10. Monthly Payroll Input | B12: =COUNTIFS('FRD Field Status'!$B$5:$B$401,$A12,'FRD Field Status'!$E$5:$E$401,"Built") | C12: =COUNTIFS('FRD Field Status'!$B$5:$B$401,$A12,'FRD Field Status'!$E$5:$E$401,"Partially Built") | D12: =COUNTIFS('FRD Field Status'!$B$5:$B$401,$A12,'FRD Field Status'!$E$5:$E$401,"Missing") | E12: =COUNTIFS('FRD Field Status'!$B$5:$B$401,$A12,'FRD Field Status'!$E$5:$E$401,"Pending Client Decision") | F12: =SUM(B12:E12) | G12: =IF(F12=0,0,B12/F12)
A13: 11. Payroll Calculation Logic | B13: =COUNTIFS('FRD Field Status'!$B$5:$B$401,$A13,'FRD Field Status'!$E$5:$E$401,"Built") | C13: =COUNTIFS('FRD Field Status'!$B$5:$B$401,$A13,'FRD Field Status'!$E$5:$E$401,"Partially Built") | D13: =COUNTIFS('FRD Field Status'!$B$5:$B$401,$A13,'FRD Field Status'!$E$5:$E$401,"Missing") | E13: =COUNTIFS('FRD Field Status'!$B$5:$B$401,$A13,'FRD Field Status'!$E$5:$E$401,"Pending Client Decision") | F13: =SUM(B13:E13) | G13: =IF(F13=0,0,B13/F13)
A14: 12. Payroll Approval Workflow | B14: =COUNTIFS('FRD Field Status'!$B$5:$B$401,$A14,'FRD Field Status'!$E$5:$E$401,"Built") | C14: =COUNTIFS('FRD Field Status'!$B$5:$B$401,$A14,'FRD Field Status'!$E$5:$E$401,"Partially Built") | D14: =COUNTIFS('FRD Field Status'!$B$5:$B$401,$A14,'FRD Field Status'!$E$5:$E$401,"Missing") | E14: =COUNTIFS('FRD Field Status'!$B$5:$B$401,$A14,'FRD Field Status'!$E$5:$E$401,"Pending Client Decision") | F14: =SUM(B14:E14) | G14: =IF(F14=0,0,B14/F14)
A15: 13. Salary Disbursal | B15: =COUNTIFS('FRD Field Status'!$B$5:$B$401,$A15,'FRD Field Status'!$E$5:$E$401,"Built") | C15: =COUNTIFS('FRD Field Status'!$B$5:$B$401,$A15,'FRD Field Status'!$E$5:$E$401,"Partially Built") | D15: =COUNTIFS('FRD Field Status'!$B$5:$B$401,$A15,'FRD Field Status'!$E$5:$E$401,"Missing") | E15: =COUNTIFS('FRD Field Status'!$B$5:$B$401,$A15,'FRD Field Status'!$E$5:$E$401,"Pending Client Decision") | F15: =SUM(B15:E15) | G15: =IF(F15=0,0,B15/F15)
A16: 14. Payslip | B16: =COUNTIFS('FRD Field Status'!$B$5:$B$401,$A16,'FRD Field Status'!$E$5:$E$401,"Built") | C16: =COUNTIFS('FRD Field Status'!$B$5:$B$401,$A16,'FRD Field Status'!$E$5:$E$401,"Partially Built") | D16: =COUNTIFS('FRD Field Status'!$B$5:$B$401,$A16,'FRD Field Status'!$E$5:$E$401,"Missing") | E16: =COUNTIFS('FRD Field Status'!$B$5:$B$401,$A16,'FRD Field Status'!$E$5:$E$401,"Pending Client Decision") | F16: =SUM(B16:E16) | G16: =IF(F16=0,0,B16/F16)
A17: 16. Core Data Relationships | B17: =COUNTIFS('FRD Field Status'!$B$5:$B$401,$A17,'FRD Field Status'!$E$5:$E$401,"Built") | C17: =COUNTIFS('FRD Field Status'!$B$5:$B$401,$A17,'FRD Field Status'!$E$5:$E$401,"Partially Built") | D17: =COUNTIFS('FRD Field Status'!$B$5:$B$401,$A17,'FRD Field Status'!$E$5:$E$401,"Missing") | E17: =COUNTIFS('FRD Field Status'!$B$5:$B$401,$A17,'FRD Field Status'!$E$5:$E$401,"Pending Client Decision") | F17: =SUM(B17:E17) | G17: =IF(F17=0,0,B17/F17)
... A29: 30. Configurability Acceptance Criteria | B29: =COUNTIFS('FRD Field Status'!$B$5:$B$401,$A29,'FRD Field Status'!$E$5:$E$401,"Built") | C29: =COUNTIFS('FRD Field Status'!$B$5:$B$401,$A29,'FRD Field Status'!$E$5:$E$401,"Partially Built") | D29: =COUNTIFS('FRD Field Status'!$B$5:$B$401,$A29,'FRD Field Status'!$E$5:$E$401,"Missing") | E29: =COUNTIFS('FRD Field Status'!$B$5:$B$401,$A29,'FRD Field Status'!$E$5:$E$401,"Pending Client Decision") | F29: =SUM(B29:E29) | G29: =IF(F29=0,0,B29/F29)
A30: TOTAL | B30: =SUM(B6:B29) | C30: =SUM(C6:C29) | D30: =SUM(D6:D29) | E30: =SUM(E6:E29) | F30: =SUM(F6:F29) | G30: =IF(F30=0,0,B30/F30)

Sheet FRD Field Status
A1: FRD Field Status - every field / requirement in the FRD
A2: Filter column E to see Missing or Partially Built items. Column G explains what exists or what is missing.
A4: # | B4: FRD Section | C4: Group | D4: Field / Requirement (as in FRD) | E4: Build Status | F4: Where in System | G4: What Exists / Gap
A5: 1 | B5: 3. Employee Information | C5: Basic Identity | D5: Employee ID / Code | E5: Built | F5: HRMS > Employees > Employee profile (Job / Personal tab) | G5: Auto-numbered EMP-YYYY-NNN per company
A6: 2 | B6: 3. Employee Information | C6: Basic Identity | D6: First Name | E6: Built | F6: HRMS > Employees > Employee profile (Job / Personal tab)
A7: 3 | B7: 3. Employee Information | C7: Basic Identity | D7: Middle Name | E7: Built | F7: HRMS > Employees > Employee profile (Job / Personal tab)
A8: 4 | B8: 3. Employee Information | C8: Basic Identity | D8: Last Name | E8: Built | F8: HRMS > Employees > Employee profile (Job / Personal tab)
A9: 5 | B9: 3. Employee Information | C9: Basic Identity | D9: Display Name | E9: Built | F9: HRMS > Employees > Employee profile (Job / Personal tab)
A10: 6 | B10: 3. Employee Information | C10: Basic Identity | D10: Photograph | E10: Built | F10: HRMS > Employees > Employee profile header | G10: Photograph is a profile field with upload / replace / remove; falls back to the 'Photograph' document.
A11: 7 | B11: 3. Employee Information | C11: Personal | D11: Date of Birth | E11: Built | F11: HRMS > Employees > Employee profile > Personal
A12: 8 | B12: 3. Employee Information | C12: Personal | D12: Gender | E12: Built | F12: HRMS > Employees > Employee profile > Personal
A13: 9 | B13: 3. Employee Information | C13: Personal | D13: Marital Status | E13: Built | F13: HRMS > Employees > Employee profile > Personal
A14: 10 | B14: 3. Employee Information | C14: Personal | D14: Blood Group | E14: Built | F14: HRMS > Employees > Employee profile > Personal
A15: 11 | B15: 3. Employee Information | C15: Personal | D15: Nationality | E15: Built | F15: HRMS > Employees > Employee profile > Personal
A16: 12 | B16: 3. Employee Information | C16: Contact | D16: Personal Mobile | E16: Built | F16: HRMS > Employees > Employee profile > Contact & Address | G16: Format validated; duplicate check on email / mobile
A17: 13 | B17: 3. Employee Information | C17: Contact | D17: Official Mobile | E17: Built | F17: HRMS > Employees > Employee profile > Contact & Address | G17: Format validated; duplicate check on email / mobile
A18: 14 | B18: 3. Employee Information | C18: Contact | D18: Personal Email | E18: Built | F18: HRMS > Employees > Employee profile > Contact & Address | G18: Format validated; duplicate check on email / mobile
A19: 15 | B19: 3. Employee Information | C19: Contact | D19: Official Email | E19: Built | F19: HRMS > Employees > Employee profile > Contact & Address | G19: Format validated; duplicate check on email / mobile
A20: 16 | B20: 3. Employee Information | C20: Current Address | D20: Address Line 1 | E20: Built | F20: HRMS > Employees > Employee profile > Contact & Address | G20: PIN validated as 6 digits for India
A21: 17 | B21: 3. Employee Information | C21: Current Address | D21: Address Line 2 | E21: Built | F21: HRMS > Employees > Employee profile > Contact & Address | G21: PIN validated as 6 digits for India
A22: 18 | B22: 3. Employee Information | C22: Current Address | D22: City | E22: Built | F22: HRMS > Employees > Employee profile > Contact & Address | G22: PIN validated as 6 digits for India
A23: 19 | B23: 3. Employee Information | C23: Current Address | D23: District | E23: Built | F23: HRMS > Employees > Employee profile > Contact & Address | G23: PIN validated as 6 digits for India
A24: 20 | B24: 3. Employee Information | C24: Current Address | D24: State | E24: Built | F24: HRMS > Employees > Employee profile > Contact & Address | G24: PIN validated as 6 digits for India
A25: 21 | B25: 3. Employee Information | C25: Current Address | D25: PIN Code | E25: Built | F25: HRMS > Employees > Employee profile > Contact & Address | G25: PIN validated as 6 digits for India
A26: 22 | B26: 3. Employee Information | C26: Current Address | D26: Country | E26: Built | F26: HRMS > Employees > Employee profile > Contact & Address | G26: PIN validated as 6 digits for India
A27: 23 | B27: 3. Employee Information | C27: Permanent Address | D27: Address Line 1 | E27: Built | F27: HRMS > Employees > Employee profile > Contact & Address
A28: 24 | B28: 3. Employee Information | C28: Permanent Address | D28: Address Line 2 | E28: Built | F28: HRMS > Employees > Employee profile > Contact & Address
A29: 25 | B29: 3. Employee Information | C29: Permanent Address | D29: City | E29: Built | F29: HRMS > Employees > Employee profile > Contact & Address
A30: 26 | B30: 3. Employee Information | C30: Permanent Address | D30: District | E30: Built | F30: HRMS > Employees > Employee profile > Contact & Address
A31: 27 | B31: 3. Employee Information | C31: Permanent Address | D31: State | E31: Built | F31: HRMS > Employees > Employee profile > Contact & Address
A32: 28 | B32: 3. Employee Information | C32: Permanent Address | D32: PIN Code | E32: Built | F32: HRMS > Employees > Employee profile > Contact & Address
A33: 29 | B33: 3. Employee Information | C33: Permanent Address | D33: Country | E33: Built | F33: HRMS > Employees > Employee profile > Contact & Address
A34: 30 | B34: 3. Employee Information | C34: Permanent Address | D34: Same-as-current flag | E34: Built | F34: HRMS > Employees > Employee profile > Contact & Address
A35: 31 | B35: 3. Employee Information | C35: Emergency Contact | D35: Contact Name | E35: Built | F35: HRMS > Employees > Employee profile > Contact & Address
A36: 32 | B36: 3. Employee Information | C36: Emergency Contact | D36: Relationship | E36: Built | F36: HRMS > Employees > Employee profile > Contact & Address
A37: 33 | B37: 3. Employee Information | C37: Emergency Contact | D37: Mobile | E37: Built | F37: HRMS > Employees > Employee profile > Contact & Address
A38: 34 | B38: 3. Employee Information | C38: Emergency Contact | D38: Alternate Number | E38: Built | F38: HRMS > Employees > Employee profile > Contact & Address
... A44: 40 | B44: 3. Employee Information | C44: Employment | D44: Confirmation Date | E44: Built | F44: HRMS > Employees > Employee profile > Job & Organisation
A45: 41 | B45: 3. Employee Information | C45: Organisation | D45: Company / Legal Entity | E45: Built | F45: HRMS > Employees > Employee profile > Job & Organisation | G45: Dropdown values maintained in Employee Master Setup
A46: 42 | B46: 3. Employee Information | C46: Organisation | D46: Business Unit / Branch | E46: Built | F46: HRMS > Employees > Employee profile > Job & Organisation | G46: Dropdown values maintained in Employee Master Setup
...

Sheet Missing & Partial Report
A1: Report: fields not fully built (Missing, then Partially Built, then Pending Client Decision)
A3: # | B3: Build Status | C3: FRD Section | D3: Group | E3: Field / Requirement | F3: Gap
A4: 1 | B4: Partially Built | C4: 30. Configurability Acceptance Criteria | D4: Criterion | E4: Configuration changes audited with requester, approver, reason, date, old / new | F4: Full record (requester, approver, reason, date, old / new) for everything through the approval flow, now including salary components. The company attendance-rules screen and fields outside the approval flow record author, reason and old / new but no approver.
A5: 2 | B5: Pending Client Decision | C5: 9. Salary Structure Fields | D5: Deductions | E5: PF; ESI; PT; TDS | F5: PF / ESI / PT / TDS exist as manual inputs and can be set up as components; statutory rules await the client's section 19 decision.
A6: 3 | B6: Pending Client Decision | C6: 11. Payroll Calculation Logic | D6: Formula | E6: Statutory applicability and formulas | F6: FRD sections 11 / 19 leave statutory rules to the payroll workshop.
A7: 4 | B7: Pending Client Decision | C7: 14. Payslip | D7: Template | E7: Sparsh-approved format; version retained per payroll period | F7: Template versioning and per-period freeze built; the Sparsh-approved format is still to come (section 19).

Sheet Missing Values (FRD)
A1: Values the FRD itself leaves undefined - to be confirmed by Sparsh Magic (nothing filled in by assumption)
A3: # | B3: FRD Section | C3: Item | D3: What the FRD says | E3: Missing Value | F3: Value (to be filled by client)
A4: 1 | B4: 19 | C4: Employee Categories | D4: Final list and applicability | E4: Not provided in the FRD
A5: 2 | B5: 19 | C5: Attendance Source | D5: Google, biometric, API, manual/import or combination | E5: Not in the FRD. Repo note says the client answered on 19 Oct: source is a label, no integration
A6: 3 | B6: 19 | C6: Late / Half-Day / LOP Rules | D6: Exact thresholds after grace / buffer | E6: Not provided in the FRD
A7: 4 | B7: 19 | C7: Monthly Attendance Cut-off | D7: Date and unlock authority | E7: Not provided in the FRD
A8: 5 | B8: 19 | C8: Salary Components | D8: Complete earning, deduction and employer-contribution catalogue | E8: Not provided in the FRD
A9: 6 | B9: 19 | C9: Statutory Applicability | D9: PF / ESI / PT / TDS and entity / location rules | E9: Not provided in the FRD
A10: 7 | B10: 19 | C10: Payroll Approval Matrix | D10: Exact maker / checker / finance approvers | E10: Not provided in the FRD
A11: 8 | B11: 19 | C11: Bank File Format | D11: Bank-specific layout and mandatory fields | E11: Not provided in the FRD
A12: 9 | B12: 19 | C12: Payslip Format | D12: Final approved Sparsh Magic payslip template | E12: Not provided in the FRD
A13: 10 | B13: 19 | C13: Payslip Release | D13: Immediate after approval or after confirmed bank processing | E13: Not decided in the FRD
A14: 11 | B14: 19 | C14: Payment Failure Process | D14: Owner and retry / reversal procedure | E14: Not provided in the FRD
A15: 12 | B15: 1 / 11 | C15: Statutory formulas (PF, ESI, PT, TDS) | D15: Subject to payroll workshop | E15: Not provided in the FRD
... A25: 22 | B25: 15 | C25: ER Diagram (page 8) | D25: Page 8 carries only the caption; the diagram is on page 7 | E25: Page 8 body empty

Sheet Defects Found
A1: Defects in existing code found by the 24 Oct re-audit
A3: # | B3: Defect | C3: FRD Sections | D3: What happens | E3: Status
A4: 1 | B4: Salary component approval not enforced | C4: 24 Lifecycle; 25 Formula Versioning; 27 Draft; 30 | D4: Salary components are governed by default, but the component save never checked it, so the Component Editor changed a live formula or set lifecycle Active with no approval. | E4: FIXED 24 Oct: live revisions are staged and go through the approval flow.
A5: 2 | B5: Payroll Policy screen's approval settings dropped | C5: 21 Payroll Policy; 12 approval matrix | D5: PayrollPolicy.jsx sent checker_required, approver_distinct_from_checker and lock_cap; PayrollPolicyIn had no such fields, so they were silently discarded. | E5: FIXED 24 Oct: the request model accepts them.
A6: 3 | B6: Regularisation request type dropped | C6: 23 OD / Regularisation request types | D6: The service validates request_type against the configured types, but RegularizationIn had no such field, so with types configured every request was refused. | E6: FIXED 24 Oct: the request model and form carry the request type.
A7: 4 | B7: Drafted change requests could not be sent for approval | C7: 27 Request -> Approval | D7: Payroll Policy, field and component changes create a Draft request, and no screen could analyse, simulate or submit it -- the approver only sees Pending Approval. | E7: FIXED 24 Oct: the Approval Inbox lets the drafter run simulation and send for approval.
